<?xml version='1.0'?>

<robot name="my_robot" xmlns:xacro="http://www.ros.org/wiki/xacro">
  
  <xacro:include filename="$(find my_robot)/urdf/my_robot.gazebo" />

  <link name="robot_footprint"></link>

  <joint name="robot_footprint_joint" type="fixed">
    <origin xyz="0 0 0" rpy="0 0 0" />
    <parent link="robot_footprint"/>
    <child link="chassis" />
  </joint>

  <link name='chassis'>
    <pose>0 0 0.07 0 0 0</pose>

    <inertial>
      <mass value="30"/>
      <origin xyz="0.0 0 0" rpy=" 0 0 0"/>
      <inertia
          ixx="0.1" ixy="0" ixz="0"
          iyy="0.1" iyz="0"
          izz="0.1"
      />
    </inertial>

    <collision name='chassis'>
      <origin xyz="0 0 0" rpy=" 0 0 0"/> 
      <geometry>
        <box size=".4 .3 .1"/>
      </geometry>
    </collision>

    <visual name='chassis'>
      <origin xyz="0 0 0" rpy=" 0 0 0"/>
      <geometry>
        <box size=".4 .3 .1"/>
      </geometry>
    </visual>
    
  </link>
  
  <link name='rack'>

    <collision name='rack'>
      <origin xyz="-0.05 0 0.13" rpy=" 0 0 0"/> 
      <geometry>
        <box size=".3 .26 .01"/>
      </geometry>
    </collision>
    
    <visual name='rack'>
      <origin xyz="-0.05 0 0.13" rpy=" 0 0 0"/>
      <geometry>
        <box size=".3 .26 .01"/>
      </geometry>
    </visual>

    <collision name='rack'>
      <origin xyz="-0.05 0.12 0.09" rpy=" 0 0 0"/> 
      <geometry>
        <box size=".3 .02 .07"/>
      </geometry>
    </collision>
    
    <visual name='rack'>
      <origin xyz="-0.05 0.12 0.09" rpy=" 0 0 0"/>
      <geometry>
        <box size=".3 .02 .07"/>
      </geometry>
    </visual>

    <collision name='rack'>
      <origin xyz="-0.05 -0.12 0.09" rpy=" 0 0 0"/> 
      <geometry>
        <box size=".3 .02 .07"/>
      </geometry>
    </collision>
    
    <visual name='rack'>
      <origin xyz="-0.05 -0.12 0.09" rpy=" 0 0 0"/>
      <geometry>
        <box size=".3 .02 .07"/>
      </geometry>
    </visual>
    
  </link>
  
  <joint name="chassis_rack_joint" type="fixed">
    <origin xyz="0 0 0" rpy="0 0 0" />
    <parent link="chassis"/>
    <child link="rack" />
  </joint>
  
  <link name='back_left_wheel'>
    <pose>0 0 0 0 0 0</pose>
  
    <inertial>
      <mass value="5"/>
      <origin xyz="0 0 0" rpy=" 0 1.5707 1.5707"/>
      <inertia
          ixx="0.1" ixy="0" ixz="0"
          iyy="0.1" iyz="0"
          izz="0.1"
      />
    </inertial>

    <collision name='back_left_wheel'>
      <origin xyz="0 0 0" rpy=" 0 1.5707 1.5707"/> 
      <geometry>
        <cylinder length="0.03" radius="0.06"/>
      </geometry>
    </collision>
    
    <visual name='back_left_wheel'>
      <origin xyz="0 0 0" rpy=" 0 1.5707 1.5707"/>
      <geometry>
        <cylinder length="0.03" radius="0.06"/>
      </geometry>
    </visual>
    
  </link>
  
  <link name='front_left_wheel'>
    <pose>0 0 0 0 0 0</pose>
  
    <inertial>
      <mass value="5"/>
      <origin xyz="0 0 0" rpy=" 0 1.5707 1.5707"/>
      <inertia
          ixx="0.1" ixy="0" ixz="0"
          iyy="0.1" iyz="0"
          izz="0.1"
      />
    </inertial>

    <collision name='front_left_wheel'>
      <origin xyz="0 0 0" rpy=" 0 1.5707 1.5707"/> 
      <geometry>
        <cylinder length="0.03" radius="0.06"/>
      </geometry>
    </collision>
    
    <visual name='front_left_wheel'>
      <origin xyz="0 0 0" rpy=" 0 1.5707 1.5707"/>
      <geometry>
        <cylinder length="0.03" radius="0.06"/>
      </geometry>
    </visual>
    
  </link>
  
  <link name='back_right_wheel'>
    <pose>0 0 0 0 0 0</pose>
  
    <inertial>
      <mass value="5"/>
      <origin xyz="0 0 0" rpy=" 0 1.5707 1.5707"/>
      <inertia
          ixx="0.1" ixy="0" ixz="0"
          iyy="0.1" iyz="0"
          izz="0.1"
      />
    </inertial>
  
    <collision name='back_right_wheel'>
      <origin xyz="0 0 0" rpy=" 0 1.5707 1.5707"/> 
      <geometry>
        <cylinder length="0.03" radius="0.06"/>
      </geometry>
    </collision>
    
    <visual name='back_right_wheel'>
      <origin xyz="0 0 0" rpy=" 0 1.5707 1.5707"/>
      <geometry>
        <cylinder length="0.03" radius="0.06"/>
      </geometry>
    </visual>
    
  </link>
  
  <link name='front_right_wheel'>
    <pose>0 0 0 0 0 0</pose>
  
    <inertial>
      <mass value="5"/>
      <origin xyz="0 0 0" rpy=" 0 1.5707 1.5707"/>
      <inertia
          ixx="0.1" ixy="0" ixz="0"
          iyy="0.1" iyz="0"
          izz="0.1"
      />
    </inertial>

    <collision name='front_right_wheel'>
      <origin xyz="0 0 0" rpy=" 0 1.5707 1.5707"/> 
      <geometry>
        <cylinder length="0.03" radius="0.06"/>
      </geometry>
    </collision>
    
    <visual name='front_right_wheel'>
      <origin xyz="0 0 0" rpy=" 0 1.5707 1.5707"/>
      <geometry>
        <cylinder length="0.03" radius="0.06"/>
      </geometry>
    </visual>
    
  </link>

  <joint type="continuous" name="back_left_wheel_joint">
    <origin xyz="-0.1 0.18 0" rpy="0 0 0"/>
    <child link="back_left_wheel"/>
    <parent link="chassis"/>
    <axis xyz="0 1 0" rpy="0 0 0"/>
    <limit effort="10000" velocity="1000"/>
    <dynamics damping="1.0" friction="1.0"/>
  </joint>
  
  <joint type="continuous" name="front_left_wheel_joint">
    <origin xyz="0.1 0.18 0" rpy="0 0 0"/>
    <child link="front_left_wheel"/>
    <parent link="chassis"/>
    <axis xyz="0 1 0" rpy="0 0 0"/>
    <limit effort="10000" velocity="1000"/>
    <dynamics damping="1.0" friction="1.0"/>
  </joint>
  
  <joint type="continuous" name="back_right_wheel_joint">
    <origin xyz="-0.1 -0.18 0" rpy="0 0 0"/>
    <child link="back_right_wheel"/>
    <parent link="chassis"/>
    <axis xyz="0 1 0" rpy="0 0 0"/>
    <limit effort="10000" velocity="1000"/>
    <dynamics damping="1.0" friction="1.0"/>
  </joint>
  
  <joint type="continuous" name="front_right_wheel_joint">
    <origin xyz="0.1 -0.18 0" rpy="0 0 0"/>
    <child link="front_right_wheel"/>
    <parent link="chassis"/>
    <axis xyz="0 1 0" rpy="0 0 0"/>
    <limit effort="10000" velocity="1000"/>
    <dynamics damping="1.0" friction="1.0"/>
  </joint>
  
  <link name='camera'>
    <pose>0 0 0 0 0 0</pose>

    <inertial>
      <mass value="0.1"/>
      <origin xyz="0.05 0.05 0.05" rpy=" 0 0 0"/>
      <inertia
          ixx="1e-6" ixy="0" ixz="0"
          iyy="1e-6" iyz="0"
          izz="1e-6"
      />
    </inertial>

    <collision name='camera'>
      <origin xyz="0 0 0" rpy=" 0 0 0"/> 
      <geometry>
        <box size="0.073 0.276 0.072"/>
      </geometry>
    </collision>

    <visual name='camera'>
      <origin xyz="0 0 0" rpy=" 0 0 0"/>
      <geometry>
        <mesh filename="package://my_robot/meshes/kinect.dae"/>
      </geometry>
    </visual>
    
  </link>
    
  <joint type="fixed" name="camera_joint">
    <origin xyz="0.18 0 0.1" rpy="0 0 0"/>
    <child link="camera"/>
    <parent link="chassis"/>
    <axis xyz="0 1 0" rpy="0 0 0"/>
  </joint>
    
  <link name='hokuyo'>
    <pose>0 0 0 0 0 0</pose>

    <inertial>
      <mass value="1e-5"/>
      <origin xyz="0 0 0" rpy=" 0 0 0"/>
      <inertia
          ixx="1e-6" ixy="0" ixz="0"
          iyy="1e-6" iyz="0"
          izz="1e-6"
      />
    </inertial>

    <collision name='hokuyo'>
      <origin xyz="0 0 0" rpy=" 0 0 0"/> 
      <geometry>
        <box size="0.1 0.1 0.1"/>
      </geometry>
    </collision>

    <visual name='hokuyo'>
      <origin xyz="0 0 0" rpy=" 0 0 0"/>
      <geometry>
        <mesh filename="package://my_robot/meshes/hokuyo.dae"/>
      </geometry>
    </visual>
    
  </link>
    
  <joint type="fixed" name="hokuyo_joint">
    <origin xyz="0.05 0 0.17" rpy="0 0 0"/>
    <child link="hokuyo"/>
    <parent link="chassis"/>
    <axis xyz="0 1 0" rpy="0 0 0"/>
  </joint>
  
  <gazebo reference="chassis">
    <material>Gazebo/GreyTransparent</material>
  </gazebo>
  
  <gazebo reference="rack">
    <material>Gazebo/Orange</material>
  </gazebo>
  
  <gazebo reference="back_left_wheel">
    <material>Gazebo/DarkGrey</material>
  </gazebo>
  
  <gazebo reference="front_left_wheel">
    <material>Gazebo/DarkGrey</material>
  </gazebo>
  <gazebo reference="back_right_wheel">
    <material>Gazebo/DarkGrey</material>
  </gazebo>
  
  <gazebo reference="front_right_wheel">
    <material>Gazebo/DarkGrey</material>
  </gazebo>

</robot>
